using System;
using FluentAssertionsAsync.Execution;
using FluentAssertionsAsync.Extensions;
#if NET47
using FluentAssertionsAsync.Specs.Common;
#endif
using Xunit;
using Xunit.Sdk;

namespace FluentAssertionsAsync.Specs.Exceptions;

public class FunctionExceptionAssertionSpecs
{
    [Fact]
    public void When_subject_is_null_when_not_expecting_an_exception_it_should_throw()
    {
        // Arrange
        Func<int> action = null;

        // Act
        Action testAction = () =>
        {
            using var _ = new AssertionScope();
            action.Should().NotThrow("because we want to test the failure {0}", "message");
        };

        // Assert
        testAction.Should().Throw<XunitException>()
            .WithMessage("*because we want to test the failure message*found <null>*")
            .Where(e => !e.Message.Contains("NullReferenceException"));
    }

    [Fact]
    public void When_method_throws_an_empty_AggregateException_it_should_fail()
    {
        // Arrange
        Func<int> act = () => throw new AggregateException();

        // Act
        Action act2 = () => act.Should().NotThrow();

        // Assert
        act2.Should().Throw<XunitException>();
    }

#pragma warning disable xUnit1026 // Theory methods should use all of their parameters
    [Theory]
    [MemberData(nameof(AggregateExceptionTestData))]
    public void When_the_expected_exception_is_wrapped_it_should_succeed<T>(Func<int> action, T _)
        where T : Exception
    {
        // Act/Assert
        action.Should().Throw<T>();
    }

    [Theory]
    [MemberData(nameof(AggregateExceptionTestData))]
    public void When_the_expected_exception_is_not_wrapped_it_should_fail<T>(Func<int> action, T _)
        where T : Exception
    {
        // Act
        Action act2 = () => action.Should().NotThrow<T>();

        // Assert
        act2.Should().Throw<XunitException>();
    }
#pragma warning restore xUnit1026 // Theory methods should use all of their parameters

    public static TheoryData<Func<int>, Exception> AggregateExceptionTestData()
    {
        var tasks = new[]
        {
            AggregateExceptionWithLeftNestedException,
            AggregateExceptionWithRightNestedException
        };

        var types = new Exception[]
        {
            new AggregateException(),
            new ArgumentNullException(),
            new InvalidOperationException()
        };

        var data = new TheoryData<Func<int>, Exception>();

        foreach (var task in tasks)
        {
            foreach (var type in types)
            {
                data.Add(task, type);
            }
        }

        data.Add(EmptyAggregateException, new AggregateException());

        return data;
    }

    private static int AggregateExceptionWithLeftNestedException()
    {
        var ex1 = new AggregateException(new InvalidOperationException());
        var ex2 = new ArgumentNullException();
        var wrapped = new AggregateException(ex1, ex2);

        throw wrapped;
    }

    private static int AggregateExceptionWithRightNestedException()
    {
        var ex1 = new ArgumentNullException();
        var ex2 = new AggregateException(new InvalidOperationException());
        var wrapped = new AggregateException(ex1, ex2);

        throw wrapped;
    }

    private static int EmptyAggregateException()
    {
        throw new AggregateException();
    }

    [Fact]
    public void Function_Assertions_should_expose_subject()
    {
        // Arrange
        Func<int> f = () => throw new ArgumentNullException();

        // Act
        Func<int> subject = f.Should().Subject;

        // Assert
        subject.Should().BeSameAs(f);
    }

    #region Throw

    [Fact]
    public void When_subject_is_null_when_an_exception_should_be_thrown_it_should_throw()
    {
        // Arrange
        Func<int> act = null;

        // Act
        Action action = () =>
        {
            using var _ = new AssertionScope();
            act.Should().Throw<ArgumentNullException>("because we want to test the failure {0}", "message");
        };

        // Assert
        action.Should().Throw<XunitException>()
            .WithMessage("*because we want to test the failure message*found <null>*")
            .Where(e => !e.Message.Contains("NullReferenceException"));
    }

    [Fact]
    public void When_function_throws_the_expected_exception_it_should_succeed()
    {
        // Arrange
        Func<int> f = () => throw new ArgumentNullException();

        // Act / Assert
        f.Should().Throw<ArgumentNullException>();
    }

    [Fact]
    public void When_function_throws_subclass_of_the_expected_exception_it_should_succeed()
    {
        // Arrange
        Func<int> f = () => throw new ArgumentNullException();

        // Act / Assert
        f.Should().Throw<ArgumentException>();
    }

    [Fact]
    public void When_function_does_not_throw_expected_exception_it_should_fail()
    {
        // Arrange
        Func<int> f = () => throw new ArgumentNullException();

        // Act
        Action action = () => f.Should().Throw<InvalidCastException>();

        // Assert
        action.Should().Throw<XunitException>()
            .WithMessage("Expected*InvalidCastException*but*ArgumentNullException*");
    }

    [Fact]
    public void When_function_does_not_throw_expected_exception_but_throws_aggregate_it_should_fail_with_inner_exception()
    {
        // Arrange
        Func<int> f = () => throw new AggregateException(new ArgumentNullException());

        // Act
        Action action = () => f.Should().Throw<InvalidCastException>();

        // Assert
        action.Should().Throw<XunitException>()
            .WithMessage("Expected*InvalidCastException*but*ArgumentNullException*");
    }

    [Fact]
    public void When_function_does_throw_expected_exception_but_in_aggregate_it_should_succeed()
    {
        // Arrange
        Func<int> f = () => throw new AggregateException(new ArgumentNullException());

        // Act
        Action action = () => f.Should().Throw<ArgumentNullException>();

        // Assert
        action.Should().NotThrow();
    }

    [Fact]
    public void
        When_function_does_not_throw_expected_exception_but_throws_aggregate_in_aggregate_it_should_fail_with_inner_exception_one_level_deep()
    {
        // Arrange
        Func<int> f = () => throw new AggregateException(new AggregateException(new ArgumentNullException()));

        // Act
        Action action = () => f.Should().Throw<InvalidCastException>();

        // Assert
        action.Should().Throw<XunitException>()
            .WithMessage("Expected*InvalidCastException*but*ArgumentNullException*");
    }

    [Fact]
    public void When_function_does_throw_expected_exception_but_in_aggregate_in_aggregate_it_should_succeed()
    {
        // Arrange
        Func<int> f = () => throw new AggregateException(new AggregateException(new ArgumentNullException()));

        // Act
        Action action = () => f.Should().Throw<ArgumentNullException>();

        // Assert
        action.Should().NotThrow();
    }

    [Fact]
    public void When_function_does_not_throw_any_exception_it_should_fail()
    {
        // Arrange
        Func<int> f = () => 12;

        // Act
        Action action = () => f.Should().Throw<InvalidCastException>("that's what I {0}", "said");

        // Assert
        action.Should().Throw<XunitException>()
            .WithMessage("Expected*InvalidCastException*that's what I said*but*no exception*");
    }

    #endregion

    #region ThrowExactly

    [Fact]
    public void When_subject_is_null_when_an_exact_exception_should_be_thrown_it_should_throw()
    {
        // Arrange
        Func<int> act = null;

        // Act
        Action action = () =>
        {
            using var _ = new AssertionScope();
            act.Should().ThrowExactly<ArgumentNullException>("because we want to test the failure {0}", "message");
        };

        // Assert
        action.Should().Throw<XunitException>()
            .WithMessage("*because we want to test the failure message*found <null>*")
            .Where(e => !e.Message.Contains("NullReferenceException"));
    }

    [Fact]
    public void When_function_throws_the_expected_exact_exception_it_should_succeed()
    {
        // Arrange
        Func<int> f = () => throw new ArgumentNullException();

        // Act / Assert
        f.Should().ThrowExactly<ArgumentNullException>();
    }

    [Fact]
    public void When_function_throws_aggregate_exception_with_inner_exception_of_the_expected_exact_exception_it_should_fail()
    {
        // Arrange
        Func<int> f = () => throw new AggregateException(new ArgumentException());

        // Act
        Action action = () => f.Should().ThrowExactly<ArgumentException>();

        // Assert
        action.Should().Throw<XunitException>()
            .WithMessage("Expected*ArgumentException*but*AggregateException*");
    }

    [Fact]
    public void When_function_throws_subclass_of_the_expected_exact_exception_it_should_fail()
    {
        // Arrange
        Func<int> f = () => throw new ArgumentNullException();

        // Act
        Action action = () => f.Should().ThrowExactly<ArgumentException>();

        // Assert
        action.Should().Throw<XunitException>()
            .WithMessage("Expected*ArgumentException*but*ArgumentNullException*");
    }

    [Fact]
    public void When_function_does_not_throw_expected_exact_exception_it_should_fail()
    {
        // Arrange
        Func<int> f = () => throw new ArgumentNullException();

        // Act
        Action action = () => f.Should().ThrowExactly<InvalidCastException>();

        // Assert
        action.Should().Throw<XunitException>()
            .WithMessage("Expected*InvalidCastException*but*ArgumentNullException*");
    }

    [Fact]
    public void When_function_does_not_throw_any_exception_when_expected_exact_it_should_fail()
    {
        // Arrange
        Func<int> f = () => 12;

        // Act
        Action action = () => f.Should().ThrowExactly<InvalidCastException>("that's what I {0}", "said");

        // Assert
        action.Should().Throw<XunitException>()
            .WithMessage("Expected*InvalidCastException*that's what I said*but*no exception*");
    }

    #endregion

    #region NotThrow

    [Fact]
    public void When_subject_is_null_when_an_exception_should_not_be_thrown_it_should_throw()
    {
        // Arrange
        Func<int> act = null;

        // Act
        Action action = () => act.Should().NotThrow("because we want to test the failure {0}", "message");

        // Assert
        action.Should().Throw<XunitException>()
            .WithMessage("*because we want to test the failure message*found <null>*");
    }

    [Fact]
    public void When_subject_is_null_when_a_generic_exception_should_not_be_thrown_it_should_throw()
    {
        // Arrange
        Func<int> act = null;

        // Act
        Action action = () =>
        {
            using var _ = new AssertionScope();
            act.Should().NotThrow<ArgumentNullException>("because we want to test the failure {0}", "message");
        };

        // Assert
        action.Should().Throw<XunitException>()
            .WithMessage("*because we want to test the failure message*found <null>*")
            .Where(e => !e.Message.Contains("NullReferenceException"));
    }

    [Fact]
    public void When_function_does_not_throw_exception_and_that_was_expected_it_should_succeed_then_continue_assertion()
    {
        // Arrange
        Func<int> f = () => 12;

        // Act / Assert
        f.Should().NotThrow().Which.Should().Be(12);
    }

    [Fact]
    public void When_function_throw_exception_and_that_was_not_expected_it_should_fail()
    {
        // Arrange
        Func<int> f = () => throw new ArgumentNullException();

        // Act
        Action action = () => f.Should().NotThrow("that's what he {0}", "told me");

        // Assert
        action.Should().Throw<XunitException>()
            .WithMessage("*no*exception*that's what he told me*but*ArgumentNullException*");
    }

    [Fact]
    public void When_function_throw_aggregate_exception_and_that_was_not_expected_it_should_fail_with_inner_exception_in_message()
    {
        // Arrange
        Func<int> f = () => throw new AggregateException(new ArgumentNullException());

        // Act
        Action action = () => f.Should().NotThrow("that's what he {0}", "told me");

        // Assert
        action.Should().Throw<XunitException>()
            .WithMessage("*no*exception*that's what he told me*but*ArgumentNullException*");
    }

    [Fact]
    public void
        When_function_throw_aggregate_in_aggregate_exception_and_that_was_not_expected_it_should_fail_with_most_inner_exception_in_message()
    {
        // Arrange
        Func<int> f = () => throw new AggregateException(new AggregateException(new ArgumentNullException()));

        // Act
        Action action = () => f.Should().NotThrow("that's what he {0}", "told me");

        // Assert
        action.Should().Throw<XunitException>()
            .WithMessage("*no*exception*that's what he told me*but*ArgumentNullException*");
    }

    [Fact]
    public void When_an_assertion_fails_on_NotThrow_succeeding_message_should_be_included()
    {
        // Arrange
        Func<int> throwingFunction = () => throw new Exception();

        // Act
        Action act = () =>
        {
            using var _ = new AssertionScope();

            throwingFunction.Should().NotThrow()
                .And.BeNull();
        };

        // Assert
        act.Should().Throw<XunitException>()
            .WithMessage(
                "*Did not expect any exception*" +
                "*to be <null>*"
            );
    }

    #endregion

    #region NotThrowAfter

    [Fact]
    public void When_subject_is_null_it_should_throw()
    {
        // Arrange
        var waitTime = 0.Milliseconds();
        var pollInterval = 0.Milliseconds();
        Func<int> action = null;

        // Act
        Action testAction = () =>
        {
            using var _ = new AssertionScope();
            action.Should().NotThrowAfter(waitTime, pollInterval, "because we want to test the failure {0}", "message");
        };

        // Assert
        testAction.Should().Throw<XunitException>()
            .WithMessage("*because we want to test the failure message*found <null>*")
            .Where(e => !e.Message.Contains("NullReferenceException"));
    }

    [Fact]
    public void When_wait_time_is_negative_it_should_throw()
    {
        // Arrange
        var waitTime = -1.Milliseconds();
        var pollInterval = 10.Milliseconds();
        Func<int> someFunc = () => 0;

        // Act
        Action action = () =>
            someFunc.Should().NotThrowAfter(waitTime, pollInterval);

        // Assert
        action.Should().Throw<ArgumentOutOfRangeException>()
            .WithParameterName("waitTime")
            .WithMessage("*must be non-negative*");
    }

    [Fact]
    public void When_poll_interval_is_negative_it_should_throw()
    {
        // Arrange
        var waitTime = 10.Milliseconds();
        var pollInterval = -1.Milliseconds();
        Func<int> someAction = () => 0;

        // Act
        Action action = () =>
            someAction.Should().NotThrowAfter(waitTime, pollInterval);

        // Assert
        action.Should().Throw<ArgumentOutOfRangeException>()
            .WithParameterName("pollInterval")
            .WithMessage("*must be non-negative*");
    }

    [Fact]
    public void When_no_exception_should_be_thrown_after_wait_time_but_it_was_it_should_throw()
    {
        // Arrange
        var clock = new FakeClock();
        var timer = clock.StartTimer();
        var waitTime = 100.Milliseconds();
        var pollInterval = 10.Milliseconds();

        Func<int> throwLongerThanWaitTime = () =>
        {
            if (timer.Elapsed <= waitTime.Multiply(1.5))
            {
                throw new ArgumentException("An exception was forced");
            }

            return 0;
        };

        // Act
        Action action = () =>
            throwLongerThanWaitTime.Should(clock).NotThrowAfter(waitTime, pollInterval, "we passed valid arguments");

        // Assert
        action.Should().Throw<XunitException>()
            .WithMessage("Did not expect any exceptions after 100ms because we passed valid arguments*");
    }

    [Fact]
    public void When_no_exception_should_be_thrown_after_wait_time_and_none_was_it_should_not_throw()
    {
        // Arrange
        var clock = new FakeClock();
        var timer = clock.StartTimer();
        var waitTime = 100.Milliseconds();
        var pollInterval = 10.Milliseconds();

        Func<int> throwShorterThanWaitTime = () =>
        {
            if (timer.Elapsed <= waitTime.Divide(2))
            {
                throw new ArgumentException("An exception was forced");
            }

            return 0;
        };

        // Act
        Action act = () => throwShorterThanWaitTime.Should(clock).NotThrowAfter(waitTime, pollInterval);

        // Assert
        act.Should().NotThrow();
    }

    [Fact]
    public void When_no_exception_should_be_thrown_after_wait_time_the_func_result_should_be_returned()
    {
        // Arrange
        var clock = new FakeClock();
        var timer = clock.StartTimer();
        var waitTime = 100.Milliseconds();
        var pollInterval = 10.Milliseconds();

        Func<int> throwShorterThanWaitTime = () =>
        {
            if (timer.Elapsed <= waitTime.Divide(2))
            {
                throw new ArgumentException("An exception was forced");
            }

            return 42;
        };

        // Act
        Action act = () => throwShorterThanWaitTime.Should(clock).NotThrowAfter(waitTime, pollInterval)
            .Which.Should().Be(42);

        // Assert
        act.Should().NotThrow();
    }

    [Fact]
    public void When_an_assertion_fails_on_NotThrowAfter_succeeding_message_should_be_included()
    {
        // Arrange
        var waitTime = TimeSpan.Zero;
        var pollInterval = TimeSpan.Zero;
        Func<int> throwingFunction = () => throw new Exception();

        // Act
        Action act = () =>
        {
            using var _ = new AssertionScope();

            throwingFunction.Should().NotThrowAfter(waitTime, pollInterval)
                .And.BeNull();
        };

        // Assert
        act.Should().Throw<XunitException>()
            .WithMessage(
                "*Did not expect any exceptions after*" +
                "*to be <null>*"
            );
    }

    #endregion

    #region NotThrow<T>

    [Fact]
    public void
        When_function_does_not_throw_at_all_when_some_particular_exception_was_not_expected_it_should_succeed_but_then_cannot_continue_assertion()
    {
        // Arrange
        Func<int> f = () => 12;

        // Act / Assert
        f.Should().NotThrow<ArgumentException>();
    }

    [Fact]
    public void When_function_does_throw_exception_and_that_exception_was_not_expected_it_should_fail()
    {
        // Arrange
        Func<int> f = () => throw new InvalidOperationException("custom message");

        // Act
        Action action = () => f.Should().NotThrow<InvalidOperationException>("it was so {0}", "fast");

        // Assert
        action.Should().Throw<XunitException>()
            .WithMessage(
                "*Did not expect System.InvalidOperationException because it was so fast, but found System.InvalidOperationException: custom message*");
    }

    [Fact]
    public void When_function_throw_one_exception_but_other_was_not_expected_it_should_succeed()
    {
        // Arrange
        Func<int> f = () => throw new ArgumentNullException();

        // Act
        Action action = () => f.Should().NotThrow<InvalidOperationException>();

        // Assert
        action.Should().NotThrow();
    }

    #endregion
}
