using System;
using System.Threading.Tasks;
using FluentAssertionsAsync.Execution;
using FluentAssertionsAsync.Extensions;
#if NET47
using FluentAssertionsAsync.Specs.Common;
#endif
using FluentAssertionsAsync.Specs.Exceptions;
using Xunit;
using Xunit.Sdk;
using static FluentAssertionsAsync.FluentActions;

namespace FluentAssertionsAsync.Specs.Specialized;

public static class TaskOfTAssertionSpecs
{
    public class CompleteWithinAsync
    {
        [Fact]
        public async Task When_subject_is_null_it_should_fail()
        {
            // Arrange
            var timeSpan = 0.Milliseconds();
            Func<Task<int>> action = null;

            // Act
            Func<Task> testAction = () => action.Should().CompleteWithinAsync(
                timeSpan, "because we want to test the failure {0}", "message");

            // Assert
            await testAction.Should().ThrowAsync<XunitException>()
                .WithMessage("*because we want to test the failure message*found <null>*");
        }

        [Fact]
        public async Task When_subject_is_null_with_AssertionScope_it_should_fail()
        {
            // Arrange
            var timeSpan = 0.Milliseconds();
            Func<Task<int>> action = null;

            // Act
            Func<Task> testAction = async () =>
            {
                using var _ = new AssertionScope();

                await action.Should().CompleteWithinAsync(
                    timeSpan, "because we want to test the failure {0}", "message");
            };

            // Assert
            await testAction.Should().ThrowAsync<XunitException>()
                .WithMessage("*because we want to test the failure message*found <null>*");
        }

        [Fact]
        public async Task When_task_completes_fast_it_should_succeed()
        {
            // Arrange
            var timer = new FakeClock();
            var taskFactory = new TaskCompletionSource<int>();

            // Act
            Func<Task> action = async () =>
            {
                Func<Task<int>> func = () => taskFactory.Task;

                (await func.Should(timer).CompleteWithinAsync(100.Milliseconds()))
                    .Which.Should().Be(42);
            };

            taskFactory.SetResult(42);
            timer.Complete();

            // Assert
            await action.Should().NotThrowAsync();
        }

        [Fact]
        public async Task When_task_completes_and_result_is_not_expected_it_should_fail()
        {
            // Arrange
            var timer = new FakeClock();
            var taskFactory = new TaskCompletionSource<int>();

            // Act
            Func<Task> action = async () =>
            {
                Func<Task<int>> funcSubject = () => taskFactory.Task;

                (await funcSubject.Should(timer).CompleteWithinAsync(100.Milliseconds()))
                    .Which.Should().Be(42);
            };

            taskFactory.SetResult(99);
            timer.Complete();

            // Assert
            // TODO message currently shows "Expected (await funcSubject to be...", but should be "Expected funcSubject to be...",
            // maybe with or without await.
            await action.Should().ThrowAsync<XunitException>().WithMessage("*to be 42, but found 99 (difference of 57).");
        }

        [Fact]
        public async Task When_task_completes_and_async_result_is_not_expected_it_should_fail()
        {
            // Arrange
            var timer = new FakeClock();
            var taskFactory = new TaskCompletionSource<int>();

            // Act
            Func<Task> action = async () =>
            {
                Func<Task<int>> funcSubject = () => taskFactory.Task;

                await funcSubject.Should(timer).CompleteWithinAsync(100.Milliseconds()).WithResult(42);
            };

            taskFactory.SetResult(99);
            timer.Complete();

            // Assert
            await action.Should().ThrowAsync<XunitException>().WithMessage("Expected funcSubject to be 42, but found 99.");
        }

        [Fact]
        public async Task When_task_completes_late_it_should_fail()
        {
            // Arrange
            var timer = new FakeClock();
            var taskFactory = new TaskCompletionSource<int>();

            // Act
            Func<Task> action = () =>
            {
                Func<Task<int>> func = () => taskFactory.Task;

                return func.Should(timer).CompleteWithinAsync(100.Milliseconds());
            };

            timer.Complete();

            // Assert
            await action.Should().ThrowAsync<XunitException>();
        }

        [Fact]
        public async Task When_task_completes_late_it_in_assertion_scope_should_fail()
        {
            // Arrange
            var timer = new FakeClock();
            var taskFactory = new TaskCompletionSource<int>();

            // Act
            Func<Task> action = async () =>
            {
                Func<Task<int>> func = () => taskFactory.Task;

                using var _ = new AssertionScope();
                await func.Should(timer).CompleteWithinAsync(100.Milliseconds());
            };

            timer.Complete();

            // Assert
            await action.Should().ThrowAsync<XunitException>();
        }

        [Fact]
        public async Task When_task_does_not_complete_the_result_extension_does_not_hang()
        {
            // Arrange
            var timer = new FakeClock();
            var taskFactory = new TaskCompletionSource<int>();

            // Act
            Func<Task> action = async () =>
            {
                Func<Task<int>> func = () => taskFactory.Task;
                using var _ = new AssertionScope();
                await func.Should(timer).CompleteWithinAsync(100.Milliseconds()).WithResult(2);
            };

            timer.Complete();

            // Assert
            var assertionTask = action.Should().ThrowAsync<XunitException>()
                .WithMessage("Expected*to complete within 100ms.*Expected*to be 2, but found 0.");

            await Awaiting(() => assertionTask).Should().CompleteWithinAsync(200.Seconds());
        }

        [Fact]
        public async Task When_task_consumes_time_in_sync_portion_it_should_fail()
        {
            // Arrange
            var timer = new FakeClock();
            var taskFactory = new TaskCompletionSource<int>();

            // Act
            Func<Task> action = () =>
            {
                Func<Task<int>> func = () =>
                {
                    timer.Delay(101.Milliseconds());
                    return taskFactory.Task;
                };

                return func.Should(timer).CompleteWithinAsync(100.Milliseconds());
            };

            taskFactory.SetResult(99);
            timer.Complete();

            // Assert
            await action.Should().ThrowAsync<XunitException>();
        }
    }

    public class NotThrowAsync
    {
        [Fact]
        public async Task When_subject_is_null_it_should_fail()
        {
            // Arrange
            Func<Task<int>> action = null;

            // Act
            Func<Task> testAction = async () =>
            {
                using var _ = new AssertionScope();
                await action.Should().NotThrowAsync("because we want to test the failure {0}", "message");
            };

            // Assert
            await testAction.Should().ThrowAsync<XunitException>()
                .WithMessage("*because we want to test the failure message*found <null>*")
                .Where(e => !e.Message.Contains("NullReferenceException"));
        }

        [Fact]
        public async Task When_task_does_not_throw_it_should_succeed()
        {
            // Arrange
            var timer = new FakeClock();
            var taskFactory = new TaskCompletionSource<int>();

            // Act
            Func<Task> action = async () =>
            {
                Func<Task<int>> func = () => taskFactory.Task;

                (await func.Should(timer).NotThrowAsync())
                    .Which.Should().Be(42);
            };

            taskFactory.SetResult(42);
            timer.Complete();

            // Assert
            await action.Should().NotThrowAsync();
        }

        [Fact]
        public async Task When_task_throws_it_should_fail()
        {
            // Arrange
            var timer = new FakeClock();

            // Act
            Func<Task> action = () =>
            {
                Func<Task<int>> func = () => throw new AggregateException();

                return func.Should(timer).NotThrowAsync();
            };

            // Assert
            await action.Should().ThrowAsync<XunitException>();
        }
    }

    [Collection("UIFacts")]
    public class NotThrowAsyncUIFacts
    {
        [UIFact]
        public async Task When_task_does_not_throw_it_should_succeed()
        {
            // Arrange
            var timer = new FakeClock();
            var taskFactory = new TaskCompletionSource<int>();

            // Act
            Func<Task> action = async () =>
            {
                Func<Task<int>> func = () => taskFactory.Task;

                (await func.Should(timer).NotThrowAsync())
                    .Which.Should().Be(42);
            };

            taskFactory.SetResult(42);
            timer.Complete();

            // Assert
            await action.Should().NotThrowAsync();
        }

        [UIFact]
        public async Task When_task_throws_it_should_fail()
        {
            // Arrange
            var timer = new FakeClock();

            // Act
            Func<Task> action = () =>
            {
                Func<Task<int>> func = () => throw new AggregateException();

                return func.Should(timer).NotThrowAsync();
            };

            // Assert
            await action.Should().ThrowAsync<XunitException>();
        }
    }

    public class NotThrowAfterAsync
    {
        [Fact]
        public async Task When_subject_is_null_it_should_fail()
        {
            // Arrange
            var waitTime = 0.Milliseconds();
            var pollInterval = 0.Milliseconds();
            Func<Task<int>> action = null;

            // Act
            Func<Task> testAction = async () =>
            {
                using var _ = new AssertionScope();

                await action.Should().NotThrowAfterAsync(waitTime, pollInterval,
                    "because we want to test the failure {0}", "message");
            };

            // Assert
            await testAction.Should().ThrowAsync<XunitException>()
                .WithMessage("*because we want to test the failure message*found <null>*")
                .Where(e => !e.Message.Contains("NullReferenceException"));
        }

        [Fact]
        public async Task When_wait_time_is_negative_it_should_fail()
        {
            // Arrange
            var waitTime = -1.Milliseconds();
            var pollInterval = 10.Milliseconds();

            var asyncObject = new AsyncClass();
            Func<Task<int>> someFunc = () => asyncObject.ReturnTaskInt();

            // Act
            Func<Task> act = () => someFunc.Should().NotThrowAfterAsync(waitTime, pollInterval);

            // Assert
            await act.Should().ThrowAsync<ArgumentOutOfRangeException>()
                .WithParameterName("waitTime")
                .WithMessage("*must be non-negative*");
        }

        [Fact]
        public async Task When_poll_interval_is_negative_it_should_fail()
        {
            // Arrange
            var waitTime = 10.Milliseconds();
            var pollInterval = -1.Milliseconds();

            var asyncObject = new AsyncClass();
            Func<Task<int>> someFunc = () => asyncObject.ReturnTaskInt();

            // Act
            Func<Task> act = () => someFunc.Should().NotThrowAfterAsync(waitTime, pollInterval);

            // Assert
            await act.Should().ThrowAsync<ArgumentOutOfRangeException>()
                .WithParameterName("pollInterval")
                .WithMessage("*must be non-negative*");
        }

        [Fact]
        public async Task When_exception_is_thrown_before_timeout_it_should_fail()
        {
            // Arrange
            var waitTime = 2.Seconds();
            var pollInterval = 10.Milliseconds();

            var clock = new FakeClock();
            var timer = clock.StartTimer();
            clock.CompleteAfter(waitTime);

            Func<Task<int>> throwLongerThanWaitTime = async () =>
            {
                if (timer.Elapsed <= waitTime.Multiply(1.5))
                {
                    throw new ArgumentException("An exception was forced");
                }

                await Task.Yield();
                return 42;
            };

            // Act
            Func<Task> action = () => throwLongerThanWaitTime.Should(clock)
                .NotThrowAfterAsync(waitTime, pollInterval, "we passed valid arguments");

            // Assert
            await action.Should().ThrowAsync<XunitException>()
                .WithMessage("Did not expect any exceptions after 2s because we passed valid arguments*");
        }

        [Fact]
        public async Task When_exception_is_thrown_after_timeout_it_should_succeed()
        {
            // Arrange
            var waitTime = 6.Seconds();
            var pollInterval = 10.Milliseconds();

            var clock = new FakeClock();
            var timer = clock.StartTimer();
            clock.Delay(waitTime);

            Func<Task<int>> throwShorterThanWaitTime = async () =>
            {
                if (timer.Elapsed <= waitTime.Divide(12))
                {
                    throw new ArgumentException("An exception was forced");
                }

                await Task.Yield();
                return 42;
            };

            // Act
            Func<Task> act = async () =>
            {
                (await throwShorterThanWaitTime.Should(clock).NotThrowAfterAsync(waitTime, pollInterval))
                    .Which.Should().Be(42);
            };

            // Assert
            await act.Should().NotThrowAsync();
        }
    }

    public class NotThrowAfterAsyncUIFacts
    {
        [UIFact]
        public async Task When_exception_is_thrown_before_timeout_it_should_fail()
        {
            // Arrange
            var waitTime = 2.Seconds();
            var pollInterval = 10.Milliseconds();

            var clock = new FakeClock();
            var timer = clock.StartTimer();
            clock.CompleteAfter(waitTime);

            Func<Task<int>> throwLongerThanWaitTime = async () =>
            {
                if (timer.Elapsed <= waitTime.Multiply(1.5))
                {
                    throw new ArgumentException("An exception was forced");
                }

                await Task.Yield();
                return 42;
            };

            // Act
            Func<Task> action = () => throwLongerThanWaitTime.Should(clock)
                .NotThrowAfterAsync(waitTime, pollInterval, "we passed valid arguments");

            // Assert
            await action.Should().ThrowAsync<XunitException>()
                .WithMessage("Did not expect any exceptions after 2s because we passed valid arguments*");
        }

        [UIFact]
        public async Task When_exception_is_thrown_after_timeout_it_should_succeed()
        {
            // Arrange
            var waitTime = 6.Seconds();
            var pollInterval = 10.Milliseconds();

            var clock = new FakeClock();
            var timer = clock.StartTimer();
            clock.Delay(waitTime);

            Func<Task<int>> throwShorterThanWaitTime = async () =>
            {
                if (timer.Elapsed <= waitTime.Divide(12))
                {
                    throw new ArgumentException("An exception was forced");
                }

                await Task.Yield();
                return 42;
            };

            // Act
            Func<Task> act = async () =>
            {
                (await throwShorterThanWaitTime.Should(clock).NotThrowAfterAsync(waitTime, pollInterval))
                    .Which.Should().Be(42);
            };

            // Assert
            await act.Should().NotThrowAsync();
        }
    }
}
